<?xml version="1.0"?>

<robot name="hibachi_wheel" xmlns:xacro="http://ros.org/wiki/xacro">
    <xacro:macro name="hibachi_wheel" params="wheel_prefix *joint_pose">
        <xacro:property name="link_name" value="${wheel_prefix}_wheel_link" />
        <xacro:property name="joint_name" value="${wheel_prefix}_wheel" />
        <xacro:property name="transmission_name" value="${wheel_prefix}_wheel_trans" />
        <xacro:property name="actuator_name" value="${wheel_prefix}_wheel_actuator" />

        <link name="${link_name}">
            <visual>
                <origin xyz="0 0 0" rpy="0 0 0"/>
                <geometry>
                    <mesh filename="package://hibachi_description/meshes/wheel_12_6.dae"/>
                </geometry>
            </visual>
            <collision>
                <origin xyz="0 0 0" rpy="${PI/2} 0 0"/>
                <geometry>
                    <cylinder radius="${wheel_radius}" length="${wheel_width}"/>
                </geometry>
            </collision>
            <inertial>
                <origin xyz="0 0 0" />
                <mass value="0.150"/>
                <inertia
                    ixx="0.00018" ixy="0" ixz=  "0"
                    iyy="0.00027" iyz="0" izz="0.00018"/>
            </inertial>
        </link>

        <gazebo reference="${link_name}">
            <material>Gazebo/DarkGrey</material>
            <selfCollide>false</selfCollide>
            <mu1 value="1"/>
            <mu2 value="1"/>
            <kp value="10000000.0" />
            <kd value="1.0" />
            <fdir1 value="1 0 0"/>
        </gazebo>

        <joint name="${joint_name}" type="continuous">
            <parent link="base_link"/>
            <child link="${link_name}" />
            <xacro:insert_block name="joint_pose" />
            <axis xyz="0 1 0" rpy="0 0 0" />
        </joint>

        <transmission name="${transmission_name}">
        <type>transmission_interface/SimpleTransmission</type>
        <joint name="${joint_name}">
            <hardwareInterface>hardware_interface/VelocityJointInterface</hardwareInterface>
        </joint>
        <actuator name="${actuator_name}">
            <mechanicalReduction>1</mechanicalReduction>
        </actuator>
        </transmission>

    </xacro:macro>

</robot>
